Workbook

Sheet REV
A1: PostingDate | B1: EffectiveDate | C1: InstrumentId | D1: AttributeId | E1: ATTRIBUTE_PRODUCT_ID_CURRENT | F1: ATTRIBUTE_ITEM_STARTDATE_CURRENT | G1: ATTRIBUTE_ITEM_ENDDATE_CURRENT | H1: ATTRIBUTE_SALE_PRICE_CURRENT | I1: ATTRIBUTE_QUANTITY_CURRENT
A2: 44620.229 | B2: 44576.229 | C2: SO1 | D2: 0.0 | E2: 0
A3: 44620.229 | B3: 44576.229 | C3: SO1 | D3: 1.0 | E3: 1 | F3: 44576.229 | G3: 44576.229 | H3: -200 | I3: 1
A4: 44620.229 | B4: 44576.229 | C4: SO1 | D4: 2.0 | E4: 2 | F4: 44576.229 | G4: 44941.229 | H4: 100 | I4: 12
A5: 44620.229 | B5: 44576.229 | C5: SO1 | D5: 3.0 | E5: 3 | F5: 44576.229 | G5: 44576.229 | H5: 300 | I5: 1
A6: 44620.229 | B6: 44576.229 | C6: SO1 | D6: 4.0 | E6: 5 | F6: 44576.229 | G6: 44941.229 | H6: 50 | I6: 12

Sheet INV
A1: PostingDate | B1: EffectiveDate | C1: InstrumentId | D1: AttributeId | E1: TRANSACTIONS_AMOUNT_NEW_BILLING | F1: TRANSACTIONS_AMOUNT_CREDIT_NOTE
A2: 44620.229 | B2: 44620.229 | C2: SO1 | D2: 0.0 | E2: 1900

Sheet EOD
A1: PostingDate | B1: EffectiveDate | C1: InstrumentId | D1: AttributeId | E1: BALANCES_ENDINGBALANCE_BILLING | F1: BALANCES_ENDINGBALANCE_UNBILLED | G1: BALANCES_ENDINGBALANCE_REVENUE | H1: BALANCES_ENDINGBALANCE_DEFERRED_REVENUE
A2: 44620.229 | B2: 44620.229 | C2: SO1 | D2: 0.0 | E2: 1900 | F2: 342.818 | H2: 2242.818
A3: 44620.229 | B3: 44620.229 | C3: SO1 | D3: 1.0
A4: 44620.229 | B4: 44620.229 | C4: SO1 | D4: 2.0 | G4: -47.593 | H4: -47.593
A5: 44620.229 | B5: 44620.229 | C5: SO1 | D5: 3.0 | G5: -271.4286 | H5: -271.4286
A6: 44620.229 | B6: 44620.229 | C6: SO1 | D6: 4.0 | G6: -23.7965 | H6: -23.7965

Sheet ProductCatalog_Allocation_Calc
A1: PRODUCT CATALOG
A2: ProductId | B2: ProductName | C2: Standalone Sellig Price Rule | D2: Revenue Recognition Method | E2: Amount
A3: 1 | B3: Discount | C3: AMOUNT | D3: POINT_IN_TIME | E3: 0
A4: 2 | B4: SaaS Basic Subscription | C4: USE SALES PRICE | D4: RATABLE
A5: 3 | B5: SaaS Implementation | C5: USE SALES PRICE | D5: POINT_IN_TIME
A6: 4 | B6: SaaS Training | C6: USE SALES PRICE | D6: POINT_IN_TIME
A7: 5 | B7: SaaS Premium Subscription | C7: USE SALES PRICE | D7: RATABLE
A8: 0 | B8: Invoice
A11: REVENUE ALLOCATION
A12: ProductId | B12: ProductName | C12: Sale Price | D12: SSP | E12: Ratio | F12: Allocation
A13: =C22 -> 1 | B13: =IFERROR(VLOOKUP(A13,A3:$B$7,2,FALSE()),"") -> Discount | C13: =IFERROR(VLOOKUP(A13,REV!$E$2:$I$8,4,FALSE())*VLOOKUP(A13,REV!$E$2:$I$8,5,FALSE()),"") -> -200 | D13: =IFERROR(IF(VLOOKUP(B13,$B$3:$C$7,2,FALSE())="USE SALES PRICE",C13,VLOOKUP(B13,$B$3:$E$7,4,FALSE())),"") -> 0 | E13: =IFERROR(D13/$D$18,"") -> 0 | F13: =IFERROR(E13*$C$18,"") -> 0
A14: =C23 -> 2 | B14: =IFERROR(VLOOKUP(A14,A4:$B$7,2,FALSE()),"") -> SaaS Basic Subscription | C14: =IFERROR(VLOOKUP(A14,REV!$E$2:$I$8,4,FALSE())*VLOOKUP(A14,REV!$E$2:$I$8,5,FALSE()),"") -> 1200 | D14: =IFERROR(IF(VLOOKUP(B14,$B$3:$C$7,2,FALSE())="USE SALES PRICE",C14,VLOOKUP(B14,$B$3:$E$7,4,FALSE())),"") -> 1200 | E14: =IFERROR(D14/$D$18,"") -> 0.57142857 | F14: =IFERROR(E14*$C$18,"") -> 1085.7143
A15: =C24 -> 3 | B15: =IFERROR(VLOOKUP(A15,A5:$B$7,2,FALSE()),"") -> SaaS Implementation | C15: =IFERROR(VLOOKUP(A15,REV!$E$2:$I$8,4,FALSE())*VLOOKUP(A15,REV!$E$2:$I$8,5,FALSE()),"") -> 300 | D15: =IFERROR(IF(VLOOKUP(B15,$B$3:$C$7,2,FALSE())="USE SALES PRICE",C15,VLOOKUP(B15,$B$3:$E$7,4,FALSE())),"") -> 300 | E15: =IFERROR(D15/$D$18,"") -> 0.14285714 | F15: =IFERROR(E15*$C$18,"") -> 271.42857
A16: =C25 -> 5 | B16: =IFERROR(VLOOKUP(A16,A6:$B$7,2,FALSE()),"") -> SaaS Premium Subscription | C16: =IFERROR(VLOOKUP(A16,REV!$E$2:$I$8,4,FALSE())*VLOOKUP(A16,REV!$E$2:$I$8,5,FALSE()),"") -> 600 | D16: =IFERROR(IF(VLOOKUP(B16,$B$3:$C$7,2,FALSE())="USE SALES PRICE",C16,VLOOKUP(B16,$B$3:$E$7,4,FALSE())),"") -> 600 | E16: =IFERROR(D16/$D$18,"") -> 0.28571429 | F16: =IFERROR(E16*$C$18,"") -> 542.85714
A17: =C26 | B17: =IFERROR(VLOOKUP(A17,A7:$B$7,2,FALSE()),"") | C17: =IFERROR(VLOOKUP(A17,REV!$E$2:$I$8,4,FALSE())*VLOOKUP(A17,REV!$E$2:$I$8,5,FALSE()),"") | D17: =IFERROR(IF(VLOOKUP(B17,$B$3:$C$7,2,FALSE())="USE SALES PRICE",C17,VLOOKUP(B17,$B$3:$E$7,4,FALSE())),"") | E17: =IFERROR(D17/$D$18,"") | F17: =IFERROR(E17*$C$18,"")
A18: Total | C18: =SUM(C13:C17) -> 1900 | D18: =SUM(D13:D17) -> 2100 | E18: =SUM(E13:E17) -> 1 | F18: =SUM(F13:F17) -> 1900 | G18: =F18=C18 -> TRUE
A20: KEY HELPER
A21: ProductID | B21: AttributeID | C21: Helper PID | D21: Lookup Att
A22: =VALUE(REV!E2) -> 0 | B22: =VALUE(REV!D2) -> 0 | C22: =IFERROR(SMALL($A$22:$A$27, ROW(A1) + COUNTIF($A$22:$A$27,0)),"") -> 1 | D22: =IFERROR(VLOOKUP(C22,$A$22:$B$27,2,FALSE),"") -> 1
A23: =VALUE(REV!E3) -> 1 | B23: =VALUE(REV!D3) -> 1 | C23: =IFERROR(SMALL($A$22:$A$27, ROW(A2) + COUNTIF($A$22:$A$27,0)),"") -> 2 | D23: =IFERROR(VLOOKUP(C23,$A$22:$B$27,2,FALSE),"") -> 2
A24: =VALUE(REV!E4) -> 2 | B24: =VALUE(REV!D4) -> 2 | C24: =IFERROR(SMALL($A$22:$A$27, ROW(A3) + COUNTIF($A$22:$A$27,0)),"") -> 3 | D24: =IFERROR(VLOOKUP(C24,$A$22:$B$27,2,FALSE),"") -> 3
A25: =VALUE(REV!E5) -> 3 | B25: =VALUE(REV!D5) -> 3 | C25: =IFERROR(SMALL($A$22:$A$27, ROW(A4) + COUNTIF($A$22:$A$27,0)),"") -> 5 | D25: =IFERROR(VLOOKUP(C25,$A$22:$B$27,2,FALSE),"") -> 4
A26: =VALUE(REV!E6) -> 5 | B26: =VALUE(REV!D6) -> 4 | C26: =IFERROR(SMALL($A$22:$A$27, ROW(A5) + COUNTIF($A$22:$A$27,0)),"") | D26: =IFERROR(VLOOKUP(C26,$A$22:$B$27,2,FALSE),"")
A27: =VALUE(REV!E7) -> 0 | B27: =VALUE(REV!D7) -> 0 | C27: =IFERROR(SMALL($A$22:$A$27, ROW(A6) + COUNTIF($A$22:$A$27,0)),"") | D27: =IFERROR(VLOOKUP(C27,$A$22:$B$27,2,FALSE),"")

Sheet RevRec_Calc
A1: ALLOCATED REVENUE | J1: HEALTH CHECK | L1: EXECUTION DATE
A2: Product ID | B2: Attribute Id | C2: Revenue Allocation | D2: Start Date | E2: End Date | F2: Days | G2: Per Day Revenue | H2: InstrumentID | I2: Recognition Method | J2: Days | K2: Revenue
A3: =ProductCatalog_Allocation_Calc!A13 -> 1 | B3: =ProductCatalog_Allocation_Calc!D22 -> 1 | C3: =IF($A3="","",ProductCatalog_Allocation_Calc!F13) -> 0 | D3: =IF($A3="","",VLOOKUP(A3,REV!$E$2:$I$8,2,FALSE())) -> 44576.229 | E3: =IF($A3="","",VLOOKUP(A3,REV!$E$2:$I$8,3,FALSE())) -> 44576.229 | F3: =IF($A3="","",IF(E3-D3=0,0,E3-D3)) -> 0 | G3: =IFERROR(IF($A3="","",C3/F3),C3) -> 0 | H3: =IF($A3="","",REV!C3) -> SO1 | I3: =IF($A3="","",VLOOKUP(A3,ProductCatalog_Allocation_Calc!$A$3:$D$7,4,FALSE())) -> POINT_IN_TIME | J3: =IF(A3="","",IF(SUM(BD11:CB11)-$F3=0,"Pass","Fail")) -> Pass | K3: =IF(A3="","",IF(ROUND(SUM(CE11:DC11),4)-$C3=0,"Pass","Fail")) -> Pass | L3: =EOD!A2 -> 44620.229
A4: =ProductCatalog_Allocation_Calc!A14 -> 2 | B4: =ProductCatalog_Allocation_Calc!D23 -> 2 | C4: =IF($A4="","",ProductCatalog_Allocation_Calc!F14) -> 1085.7143 | D4: =IF($A4="","",VLOOKUP(A4,REV!$E$2:$I$8,2,FALSE())) -> 44576.229 | E4: =IF($A4="","",VLOOKUP(A4,REV!$E$2:$I$8,3,FALSE())) -> 44941.229 | F4: =IF($A4="","",IF(E4-D4=0,0,E4-D4)) -> 365 | G4: =IFERROR(IF($A4="","",C4/F4),C4) -> 2.9745597 | H4: =IF($A4="","",REV!C4) -> SO1 | I4: =IF($A4="","",VLOOKUP(A4,ProductCatalog_Allocation_Calc!$A$3:$D$7,4,FALSE())) -> RATABLE | J4: =IF(A4="","",IF(SUM(BD12:CB12)-$F4=0,"Pass","Fail")) -> Pass | K4: =IF(A4="","",IF(ROUND(SUM(CE12:DC12),4)-ROUND($C4,4)=0,"Pass","Fail")) -> Pass
A5: =ProductCatalog_Allocation_Calc!A15 -> 3 | B5: =ProductCatalog_Allocation_Calc!D24 -> 3 | C5: =IF($A5="","",ProductCatalog_Allocation_Calc!F15) -> 271.42857 | D5: =IF($A5="","",VLOOKUP(A5,REV!$E$2:$I$8,2,FALSE())) -> 44576.229 | E5: =IF($A5="","",VLOOKUP(A5,REV!$E$2:$I$8,3,FALSE())) -> 44576.229 | F5: =IF($A5="","",IF(E5-D5=0,0,E5-D5)) -> 0 | G5: =IFERROR(IF($A5="","",C5/F5),C5) -> 271.42857 | H5: =IF($A5="","",REV!C5) -> SO1 | I5: =IF($A5="","",VLOOKUP(A5,ProductCatalog_Allocation_Calc!$A$3:$D$7,4,FALSE())) -> POINT_IN_TIME | J5: =IF(A5="","",IF(SUM(BD13:CB13)-$F5=0,"Pass","Fail")) -> Pass | K5: =IF(A5="","",IF(ROUND(SUM(CE13:DC13),4)-ROUND($C5,4)=0,"Pass","Fail")) -> Pass
A6: =ProductCatalog_Allocation_Calc!A16 -> 5 | B6: =ProductCatalog_Allocation_Calc!D25 -> 4 | C6: =IF($A6="","",ProductCatalog_Allocation_Calc!F16) -> 542.85714 | D6: =IF($A6="","",VLOOKUP(A6,REV!$E$2:$I$8,2,FALSE())) -> 44576.229 | E6: =IF($A6="","",VLOOKUP(A6,REV!$E$2:$I$8,3,FALSE())) -> 44941.229 | F6: =IF($A6="","",IF(E6-D6=0,0,E6-D6)) -> 365 | G6: =IFERROR(IF($A6="","",C6/F6),C6) -> 1.4872798 | H6: =IF($A6="","",REV!C6) -> SO1 | I6: =IF($A6="","",VLOOKUP(A6,ProductCatalog_Allocation_Calc!$A$3:$D$7,4,FALSE())) -> RATABLE | J6: =IF(A6="","",IF(SUM(BD14:CB14)-$F6=0,"Pass","Fail")) -> Pass | K6: =IF(A6="","",IF(ROUND(SUM(CE14:DC14),4)-ROUND($C6,4)=0,"Pass","Fail")) -> Pass
A7: =ProductCatalog_Allocation_Calc!A17 | B7: =ProductCatalog_Allocation_Calc!D26 | C7: =IF($A7="","",ProductCatalog_Allocation_Calc!F17) | D7: =IF($A7="","",VLOOKUP(A7,REV!$E$2:$I$8,2,FALSE())) | E7: =IF($A7="","",#REF!) | F7: =IF($A7="","",IF(E7-D7=0,0,E7-D7)) | G7: =IFERROR(IF($A7="","",C7/F7),C7) | H7: =IF($A7="","",REV!C7) | I7: =IF($A7="","",VLOOKUP(A7,ProductCatalog_Allocation_Calc!$A$3:$D$7,4,FALSE())) | J7: =IF(A7="","",IF(SUM(BD15:CB15)-$F7=0,"Pass","Fail")) | K7: =IF(A7="","",IF(ROUND(SUM(CE15:DC15),4)-$C7=0,"Pass","Fail"))
A9: Months | AB9: HELPER COLUMN | BC9: DAYS | CD9: REVENUE
A10: AttributeID | B10: 0 | C10: 1 | D10: 2 | E10: 3 | F10: 4 | G10: 5 | H10: 6 | I10: 7 | J10: 8 | K10: 9 | L10: 10 | M10: 11 | N10: 12 | O10: 13 | P10: 14 | Q10: 15 | R10: 16 | S10: 17 | T10: 18 | U10: 19 | V10: 20 | W10: 21 | X10: 22 | Y10: 23 | Z10: 24 | AB10: ProductID | AC10: 0 | AD10: 1 | AE10: 2 | AF10: 3 | AG10: 4 | AH10: 5 | AI10: 6 | AJ10: 7 | AK10: 8 | AL10: 9 | AM10: 10 | AN10: 11 | AO10: 12 | AP10: 13 | AQ10: 14 | AR10: 15 | AS10: 16 | AT10: 17 | AU10: 18 | AV10: 19 | AW10: 20 | AX10: 21 | AY10: 22 | AZ10: 23 | BA10: 24 | BC10: ProductID | BD10: 0 | BE10: 1 | BF10: 2 | BG10: 3 | BH10: 4 | BI10: 5 | BJ10: 6 | BK10: 7 | BL10: 8 | BM10: 9 | BN10: 10 | BO10: 11 | BP10: 12 | BQ10: 13 | BR10: 14 | BS10: 15 | BT10: 16 | BU10: 17 | BV10: 18 | BW10: 19 | BX10: 20 | BY10: 21 | BZ10: 22 | CA10: 23 | CB10: 24 | CD10: ProductID | CE10: 0 | CF10: 1 | CG10: 2 | CH10: 3 | CI10: 4 | CJ10: 5 | CK10: 6 | CL10: 7 | CM10: 8 | CN10: 9 | CO10: 10 | CP10: 11 | CQ10: 12 | CR10: 13 | CS10: 14 | CT10: 15 | CU10: 16 | CV10: 17 | CW10: 18 | CX10: 19 | CY10: 20 | CZ10: 21 | DA10: 22 | DB10: 23 | DC10: 24
A11: =IF($B3="","",$B3) -> 1 | B11: =IF(A11="","",IF(EOMONTH($D3,B$10)=EOMONTH($E3,0),$E3,IF(EOMONTH($D3,B$10)>EOMONTH($E3,0),"",EOMONTH($D3,B$10)))) -> 44576.229 | C11: =IFERROR(IF(EOMONTH($D3,C$10)=EOMONTH($E3,0),$E3,IF(EOMONTH($D3,C$10)>EOMONTH($E3,0),"",EOMONTH($D3,C$10))),"") | D11: =IFERROR(IF(EOMONTH($D3,D$10)=EOMONTH($E3,0),$E3,IF(EOMONTH($D3,D$10)>EOMONTH($E3,0),"",EOMONTH($D3,D$10))),"") | E11: =IFERROR(IF(EOMONTH($D3,E$10)=EOMONTH($E3,0),$E3,IF(EOMONTH($D3,E$10)>EOMONTH($E3,0),"",EOMONTH($D3,E$10))),"") | F11: =IFERROR(IF(EOMONTH($D3,F$10)=EOMONTH($E3,0),$E3,IF(EOMONTH($D3,F$10)>EOMONTH($E3,0),"",EOMONTH($D3,F$10))),"") | G11: =IFERROR(IF(EOMONTH($D3,G$10)=EOMONTH($E3,0),$E3,IF(EOMONTH($D3,G$10)>EOMONTH($E3,0),"",EOMONTH($D3,G$10))),"") | H11: =IFERROR(IF(EOMONTH($D3,H$10)=EOMONTH($E3,0),$E3,IF(EOMONTH($D3,H$10)>EOMONTH($E3,0),"",EOMONTH($D3,H$10))),"") | I11: =IFERROR(IF(EOMONTH($D3,I$10)=EOMONTH($E3,0),$E3,IF(EOMONTH($D3,I$10)>EOMONTH($E3,0),"",EOMONTH($D3,I$10))),"") | J11: =IFERROR(IF(EOMONTH($D3,J$10)=EOMONTH($E3,0),$E3,IF(EOMONTH($D3,J$10)>EOMONTH($E3,0),"",EOMONTH($D3,J$10))),"") | ... Z11: =IFERROR(IF(EOMONTH($D3,Z$10)=EOMONTH($E3,0),$E3,IF(EOMONTH($D3,Z$10)>EOMONTH($E3,0),"",EOMONTH($D3,Z$10))),"") | AB11: =IF($A3="","",$A3) -> 1 | AC11: =IF($L$3>=B11,$L$3,B11) -> 44620.229 | AD11: =IF($L$3>=C11,$L$3,C11) | AE11: =IF($L$3>=D11,$L$3,D11) | AF11: =IF($L$3>=E11,$L$3,E11) | AG11: =IF($L$3>=F11,$L$3,F11) | AH11: =IF($L$3>=G11,$L$3,G11) | AI11: =IF($L$3>=H11,$L$3,H11) | AJ11: =IF($L$3>=I11,$L$3,I11) | ... BA11: =IF($L$3>=Z11,$L$3,Z11) | BC11: =IF($A3="","",$A3) -> 1 | BD11: =IFERROR(ROUND(IF(BD$10=0,B11-$D3,IF(AC11=$E3,(B11-A11),B11-A11)),0),"") -> 0 | BE11: =IFERROR(ROUND(IF(BE$10=0,C11-$D3,IF(AD11=$E3,(C11-B11),C11-B11)),0),"") | BF11: =IFERROR(ROUND(IF(BF$10=0,D11-$D3,IF(AE11=$E3,(D11-C11),D11-C11)),0),"") | BG11: =IFERROR(ROUND(IF(BG$10=0,E11-$D3,IF(AF11=$E3,(E11-D11),E11-D11)),0),"") | BH11: =IFERROR(ROUND(IF(BH$10=0,F11-$D3,IF(AG11=$E3,(F11-E11),F11-E11)),0),"") | BI11: =IFERROR(ROUND(IF(BI$10=0,G11-$D3,IF(AH11=$E3,(G11-F11),G11-F11)),0),"") | BJ11: =IFERROR(ROUND(IF(BJ$10=0,H11-$D3,IF(AI11=$E3,(H11-G11),H11-G11)),0),"") | BK11: =IFERROR(ROUND(IF(BK$10=0,I11-$D3,IF(AJ11=$E3,(I11-H11),I11-H11)),0),"") | ... CB11: =IFERROR(ROUND(IF(CB$10=0,Z11-$D3,IF(BA11=$E3,(Z11-Y11),Z11-Y11)),0),"") | CD11: =IF($A3="","",$A3) -> 1 | CE11: =IFERROR(IF(B11="","",IF(AND(CE$10=0,I3="POINT_IN_TIME"),$G3,$G3*BD11)),"") -> 0 | CF11: =IFERROR(IF(C11="","",$G3*BE11),"") | CG11: =IFERROR(IF(D11="","",$G3*BF11),"") | CH11: =IFERROR(IF(E11="","",$G3*BG11),"") | CI11: =IFERROR(IF(F11="","",$G3*BH11),"") | CJ11: =IFERROR(IF(G11="","",$G3*BI11),"") | CK11: =IFERROR(IF(H11="","",$G3*BJ11),"") | CL11: =IFERROR(IF(I11="","",$G3*BK11),"") | CM11: =IFERROR(IF(J11="","",$G3*BL11),"") | ... DC11: =IFERROR(IF(Z11="","",$G3*CB11),"")
A12: =IF($B4="","",$B4) -> 2 | B12: =IF(A12="","",IF(EOMONTH($D4,B$10)=EOMONTH($E4,0),$E4,IF(EOMONTH($D4,B$10)>EOMONTH($E4,0),"",EOMONTH($D4,B$10)))) -> 44592 | C12: =IFERROR(IF(EOMONTH($D4,C$10)=EOMONTH($E4,0),$E4,IF(EOMONTH($D4,C$10)>EOMONTH($E4,0),"",EOMONTH($D4,C$10))),"") -> 44620 | D12: =IFERROR(IF(EOMONTH($D4,D$10)=EOMONTH($E4,0),$E4,IF(EOMONTH($D4,D$10)>EOMONTH($E4,0),"",EOMONTH($D4,D$10))),"") -> 44651 | E12: =IFERROR(IF(EOMONTH($D4,E$10)=EOMONTH($E4,0),$E4,IF(EOMONTH($D4,E$10)>EOMONTH($E4,0),"",EOMONTH($D4,E$10))),"") -> 44681 | F12: =IFERROR(IF(EOMONTH($D4,F$10)=EOMONTH($E4,0),$E4,IF(EOMONTH($D4,F$10)>EOMONTH($E4,0),"",EOMONTH($D4,F$10))),"") -> 44712 | G12: =IFERROR(IF(EOMONTH($D4,G$10)=EOMONTH($E4,0),$E4,IF(EOMONTH($D4,G$10)>EOMONTH($E4,0),"",EOMONTH($D4,G$10))),"") -> 44742 | H12: =IFERROR(IF(EOMONTH($D4,H$10)=EOMONTH($E4,0),$E4,IF(EOMONTH($D4,H$10)>EOMONTH($E4,0),"",EOMONTH($D4,H$10))),"") -> 44773 | I12: =IFERROR(IF(EOMONTH($D4,I$10)=EOMONTH($E4,0),$E4,IF(EOMONTH($D4,I$10)>EOMONTH($E4,0),"",EOMONTH($D4,I$10))),"") -> 44804 | J12: =IFERROR(IF(EOMONTH($D4,J$10)=EOMONTH($E4,0),$E4,IF(EOMONTH($D4,J$10)>EOMONTH($E4,0),"",EOMONTH($D4,J$10))),"") -> 44834 | ... Z12: =IFERROR(IF(EOMONTH($D4,Z$10)=EOMONTH($E4,0),$E4,IF(EOMONTH($D4,Z$10)>EOMONTH($E4,0),"",EOMONTH($D4,Z$10))),"") | AB12: =IF($A4="","",$A4) -> 2 | AC12: =IF($L$3>=B12,$L$3,B12) -> 44620.229 | AD12: =IF($L$3>=C12,$L$3,C12) -> 44620.229 | AE12: =IF($L$3>=D12,$L$3,D12) -> 44651 | AF12: =IF($L$3>=E12,$L$3,E12) -> 44681 | AG12: =IF($L$3>=F12,$L$3,F12) -> 44712 | AH12: =IF($L$3>=G12,$L$3,G12) -> 44742 | AI12: =IF($L$3>=H12,$L$3,H12) -> 44773 | AJ12: =IF($L$3>=I12,$L$3,I12) -> 44804 | ... BA12: =IF($L$3>=Z12,$L$3,Z12) | BC12: =IF($A4="","",$A4) -> 2 | BD12: =IFERROR(ROUND(IF(BD$10=0,B12-$D4,IF(AC12=$E4,(B12-A12),B12-A12)),0),"") -> 16 | BE12: =IFERROR(ROUND(IF(BE$10=0,C12-$D4,IF(AD12=$E4,(C12-B12),C12-B12)),0),"") -> 28 | BF12: =IFERROR(ROUND(IF(BF$10=0,D12-$D4,IF(AE12=$E4,(D12-C12),D12-C12)),0),"") -> 31 | BG12: =IFERROR(ROUND(IF(BG$10=0,E12-$D4,IF(AF12=$E4,(E12-D12),E12-D12)),0),"") -> 30 | BH12: =IFERROR(ROUND(IF(BH$10=0,F12-$D4,IF(AG12=$E4,(F12-E12),F12-E12)),0),"") -> 31 | BI12: =IFERROR(ROUND(IF(BI$10=0,G12-$D4,IF(AH12=$E4,(G12-F12),G12-F12)),0),"") -> 30 | BJ12: =IFERROR(ROUND(IF(BJ$10=0,H12-$D4,IF(AI12=$E4,(H12-G12),H12-G12)),0),"") -> 31 | BK12: =IFERROR(ROUND(IF(BK$10=0,I12-$D4,IF(AJ12=$E4,(I12-H12),I12-H12)),0),"") -> 31 | ... CB12: =IFERROR(ROUND(IF(CB$10=0,Z12-$D4,IF(BA12=$E4,(Z12-Y12),Z12-Y12)),0),"") | CD12: =IF($A4="","",$A4) -> 2 | CE12: =IFERROR(IF(B12="","",IF(AND(CE$10=0,I4="POINT_IN_TIME"),$G4,$G4*BD12)),"") -> 47.592955 | CF12: =IFERROR(IF(C12="","",$G4*BE12),"") -> 83.287671 | CG12: =IFERROR(IF(D12="","",$G4*BF12),"") -> 92.21135 | CH12: =IFERROR(IF(E12="","",$G4*BG12),"") -> 89.236791 | CI12: =IFERROR(IF(F12="","",$G4*BH12),"") -> 92.21135 | CJ12: =IFERROR(IF(G12="","",$G4*BI12),"") -> 89.236791 | CK12: =IFERROR(IF(H12="","",$G4*BJ12),"") -> 92.21135 | CL12: =IFERROR(IF(I12="","",$G4*BK12),"") -> 92.21135 | CM12: =IFERROR(IF(J12="","",$G4*BL12),"") -> 89.236791 | ... DC12: =IFERROR(IF(Z12="","",$G4*CB12),"")
A13: =IF($A5="","",$A5) -> 3 | B13: =IF(A13="","",IF(EOMONTH($D5,B$10)=EOMONTH($E5,0),$E5,IF(EOMONTH($D5,B$10)>EOMONTH($E5,0),"",EOMONTH($D5,B$10)))) -> 44576.229 | C13: =IFERROR(IF(EOMONTH($D5,C$10)=EOMONTH($E5,0),$E5,IF(EOMONTH($D5,C$10)>EOMONTH($E5,0),"",EOMONTH($D5,C$10))),"") | D13: =IFERROR(IF(EOMONTH($D5,D$10)=EOMONTH($E5,0),$E5,IF(EOMONTH($D5,D$10)>EOMONTH($E5,0),"",EOMONTH($D5,D$10))),"") | E13: =IFERROR(IF(EOMONTH($D5,E$10)=EOMONTH($E5,0),$E5,IF(EOMONTH($D5,E$10)>EOMONTH($E5,0),"",EOMONTH($D5,E$10))),"") | F13: =IFERROR(IF(EOMONTH($D5,F$10)=EOMONTH($E5,0),$E5,IF(EOMONTH($D5,F$10)>EOMONTH($E5,0),"",EOMONTH($D5,F$10))),"") | G13: =IFERROR(IF(EOMONTH($D5,G$10)=EOMONTH($E5,0),$E5,IF(EOMONTH($D5,G$10)>EOMONTH($E5,0),"",EOMONTH($D5,G$10))),"") | H13: =IFERROR(IF(EOMONTH($D5,H$10)=EOMONTH($E5,0),$E5,IF(EOMONTH($D5,H$10)>EOMONTH($E5,0),"",EOMONTH($D5,H$10))),"") | I13: =IFERROR(IF(EOMONTH($D5,I$10)=EOMONTH($E5,0),$E5,IF(EOMONTH($D5,I$10)>EOMONTH($E5,0),"",EOMONTH($D5,I$10))),"") | J13: =IFERROR(IF(EOMONTH($D5,J$10)=EOMONTH($E5,0),$E5,IF(EOMONTH($D5,J$10)>EOMONTH($E5,0),"",EOMONTH($D5,J$10))),"") | ... Z13: =IFERROR(IF(EOMONTH($D5,Z$10)=EOMONTH($E5,0),$E5,IF(EOMONTH($D5,Z$10)>EOMONTH($E5,0),"",EOMONTH($D5,Z$10))),"") | AB13: =IF($A5="","",$A5) -> 3 | AC13: =IF($L$3>=B13,$L$3,B13) -> 44620.229 | AD13: =IF($L$3>=C13,$L$3,C13) | AE13: =IF($L$3>=D13,$L$3,D13) | AF13: =IF($L$3>=E13,$L$3,E13) | AG13: =IF($L$3>=F13,$L$3,F13) | AH13: =IF($L$3>=G13,$L$3,G13) | AI13: =IF($L$3>=H13,$L$3,H13) | AJ13: =IF($L$3>=I13,$L$3,I13) | ... BA13: =IF($L$3>=Z13,$L$3,Z13) | BC13: =IF($A5="","",$A5) -> 3 | BD13: =IFERROR(ROUND(IF(BD$10=0,B13-$D5,IF(AC13=$E5,(B13-A13),B13-A13)),0),"") -> 0 | BE13: =IFERROR(ROUND(IF(BE$10=0,C13-$D5,IF(AD13=$E5,(C13-B13),C13-B13)),0),"") | BF13: =IFERROR(ROUND(IF(BF$10=0,D13-$D5,IF(AE13=$E5,(D13-C13),D13-C13)),0),"") | BG13: =IFERROR(ROUND(IF(BG$10=0,E13-$D5,IF(AF13=$E5,(E13-D13),E13-D13)),0),"") | BH13: =IFERROR(ROUND(IF(BH$10=0,F13-$D5,IF(AG13=$E5,(F13-E13),F13-E13)),0),"") | BI13: =IFERROR(ROUND(IF(BI$10=0,G13-$D5,IF(AH13=$E5,(G13-F13),G13-F13)),0),"") | BJ13: =IFERROR(ROUND(IF(BJ$10=0,H13-$D5,IF(AI13=$E5,(H13-G13),H13-G13)),0),"") | BK13: =IFERROR(ROUND(IF(BK$10=0,I13-$D5,IF(AJ13=$E5,(I13-H13),I13-H13)),0),"") | ... CB13: =IFERROR(ROUND(IF(CB$10=0,Z13-$D5,IF(BA13=$E5,(Z13-Y13),Z13-Y13)),0),"") | CD13: =IF($A5="","",$A5) -> 3 | CE13: =IFERROR(IF(B13="","",IF(AND(CE$10=0,I5="POINT_IN_TIME"),$G5,$G5*BD13)),"") -> 271.42857 | CF13: =IFERROR(IF(C13="","",$G5*BE13),"") | CG13: =IFERROR(IF(D13="","",$G5*BF13),"") | CH13: =IFERROR(IF(E13="","",$G5*BG13),"") | CI13: =IFERROR(IF(F13="","",$G5*BH13),"") | CJ13: =IFERROR(IF(G13="","",$G5*BI13),"") | CK13: =IFERROR(IF(H13="","",$G5*BJ13),"") | CL13: =IFERROR(IF(I13="","",$G5*BK13),"") | CM13: =IFERROR(IF(J13="","",$G5*BL13),"") | ... DC13: =IFERROR(IF(Z13="","",$G5*CB13),"")
A14: =IF($A6="","",$A6) -> 5 | B14: =IF(A14="","",IF(EOMONTH($D6,B$10)=EOMONTH($E6,0),$E6,IF(EOMONTH($D6,B$10)>EOMONTH($E6,0),"",EOMONTH($D6,B$10)))) -> 44592 | C14: =IFERROR(IF(EOMONTH($D6,C$10)=EOMONTH($E6,0),$E6,IF(EOMONTH($D6,C$10)>EOMONTH($E6,0),"",EOMONTH($D6,C$10))),"") -> 44620 | D14: =IFERROR(IF(EOMONTH($D6,D$10)=EOMONTH($E6,0),$E6,IF(EOMONTH($D6,D$10)>EOMONTH($E6,0),"",EOMONTH($D6,D$10))),"") -> 44651 | E14: =IFERROR(IF(EOMONTH($D6,E$10)=EOMONTH($E6,0),$E6,IF(EOMONTH($D6,E$10)>EOMONTH($E6,0),"",EOMONTH($D6,E$10))),"") -> 44681 | F14: =IFERROR(IF(EOMONTH($D6,F$10)=EOMONTH($E6,0),$E6,IF(EOMONTH($D6,F$10)>EOMONTH($E6,0),"",EOMONTH($D6,F$10))),"") -> 44712 | G14: =IFERROR(IF(EOMONTH($D6,G$10)=EOMONTH($E6,0),$E6,IF(EOMONTH($D6,G$10)>EOMONTH($E6,0),"",EOMONTH($D6,G$10))),"") -> 44742 | H14: =IFERROR(IF(EOMONTH($D6,H$10)=EOMONTH($E6,0),$E6,IF(EOMONTH($D6,H$10)>EOMONTH($E6,0),"",EOMONTH($D6,H$10))),"") -> 44773 | I14: =IFERROR(IF(EOMONTH($D6,I$10)=EOMONTH($E6,0),$E6,IF(EOMONTH($D6,I$10)>EOMONTH($E6,0),"",EOMONTH($D6,I$10))),"") -> 44804 | J14: =IFERROR(IF(EOMONTH($D6,J$10)=EOMONTH($E6,0),$E6,IF(EOMONTH($D6,J$10)>EOMONTH($E6,0),"",EOMONTH($D6,J$10))),"") -> 44834 | ... Z14: =IFERROR(IF(EOMONTH($D6,Z$10)=EOMONTH($E6,0),$E6,IF(EOMONTH($D6,Z$10)>EOMONTH($E6,0),"",EOMONTH($D6,Z$10))),"") | AB14: =IF($A6="","",$A6) -> 5 | AC14: =IF($L$3>=B14,$L$3,B14) -> 44620.229 | AD14: =IF($L$3>=C14,$L$3,C14) -> 44620.229 | AE14: =IF($L$3>=D14,$L$3,D14) -> 44651 | AF14: =IF($L$3>=E14,$L$3,E14) -> 44681 | AG14: =IF($L$3>=F14,$L$3,F14) -> 44712 | AH14: =IF($L$3>=G14,$L$3,G14) -> 44742 | AI14: =IF($L$3>=H14,$L$3,H14) -> 44773 | AJ14: =IF($L$3>=I14,$L$3,I14) -> 44804 | ... BA14: =IF($L$3>=Z14,$L$3,Z14) | BC14: =IF($A6="","",$A6) -> 5 | BD14: =IFERROR(ROUND(IF(BD$10=0,B14-$D6,IF(AC14=$E6,(B14-A14),B14-A14)),0),"") -> 16 | BE14: =IFERROR(ROUND(IF(BE$10=0,C14-$D6,IF(AD14=$E6,(C14-B14),C14-B14)),0),"") -> 28 | BF14: =IFERROR(ROUND(IF(BF$10=0,D14-$D6,IF(AE14=$E6,(D14-C14),D14-C14)),0),"") -> 31 | BG14: =IFERROR(ROUND(IF(BG$10=0,E14-$D6,IF(AF14=$E6,(E14-D14),E14-D14)),0),"") -> 30 | BH14: =IFERROR(ROUND(IF(BH$10=0,F14-$D6,IF(AG14=$E6,(F14-E14),F14-E14)),0),"") -> 31 | BI14: =IFERROR(ROUND(IF(BI$10=0,G14-$D6,IF(AH14=$E6,(G14-F14),G14-F14)),0),"") -> 30 | BJ14: =IFERROR(ROUND(IF(BJ$10=0,H14-$D6,IF(AI14=$E6,(H14-G14),H14-G14)),0),"") -> 31 | BK14: =IFERROR(ROUND(IF(BK$10=0,I14-$D6,IF(AJ14=$E6,(I14-H14),I14-H14)),0),"") -> 31 | ... CB14: =IFERROR(ROUND(IF(CB$10=0,Z14-$D6,IF(BA14=$E6,(Z14-Y14),Z14-Y14)),0),"") | CD14: =IF($A6="","",$A6) -> 5 | CE14: =IFERROR(IF(B14="","",$G6*BD14),"") -> 23.796477 | CF14: =IFERROR(IF(C14="","",$G6*BE14),"") -> 41.643836 | CG14: =IFERROR(IF(D14="","",$G6*BF14),"") -> 46.105675 | CH14: =IFERROR(IF(E14="","",$G6*BG14),"") -> 44.618395 | CI14: =IFERROR(IF(F14="","",$G6*BH14),"") -> 46.105675 | CJ14: =IFERROR(IF(G14="","",$G6*BI14),"") -> 44.618395 | CK14: =IFERROR(IF(H14="","",$G6*BJ14),"") -> 46.105675 | CL14: =IFERROR(IF(I14="","",$G6*BK14),"") -> 46.105675 | ... DC14: =IFERROR(IF(Z14="","",$G6*CB14),"")
A15: =IF($A7="","",$A7) | B15: =IF(A15="","",IF(EOMONTH($D7,B$10)=EOMONTH($E7,0),$E7,IF(EOMONTH($D7,B$10)>EOMONTH($E7,0),"",EOMONTH($D7,B$10)))) | C15: =IFERROR(IF(EOMONTH($D7,C$10)=EOMONTH($E7,0),$E7,IF(EOMONTH($D7,C$10)>EOMONTH($E7,0),"",EOMONTH($D7,C$10))),"") | D15: =IFERROR(IF(EOMONTH($D7,D$10)=EOMONTH($E7,0),$E7,IF(EOMONTH($D7,D$10)>EOMONTH($E7,0),"",EOMONTH($D7,D$10))),"") | E15: =IFERROR(IF(EOMONTH($D7,E$10)=EOMONTH($E7,0),$E7,IF(EOMONTH($D7,E$10)>EOMONTH($E7,0),"",EOMONTH($D7,E$10))),"") | F15: =IFERROR(IF(EOMONTH($D7,F$10)=EOMONTH($E7,0),$E7,IF(EOMONTH($D7,F$10)>EOMONTH($E7,0),"",EOMONTH($D7,F$10))),"") | G15: =IFERROR(IF(EOMONTH($D7,G$10)=EOMONTH($E7,0),$E7,IF(EOMONTH($D7,G$10)>EOMONTH($E7,0),"",EOMONTH($D7,G$10))),"") | H15: =IFERROR(IF(EOMONTH($D7,H$10)=EOMONTH($E7,0),$E7,IF(EOMONTH($D7,H$10)>EOMONTH($E7,0),"",EOMONTH($D7,H$10))),"") | I15: =IFERROR(IF(EOMONTH($D7,I$10)=EOMONTH($E7,0),$E7,IF(EOMONTH($D7,I$10)>EOMONTH($E7,0),"",EOMONTH($D7,I$10))),"") | J15: =IFERROR(IF(EOMONTH($D7,J$10)=EOMONTH($E7,0),$E7,IF(EOMONTH($D7,J$10)>EOMONTH($E7,0),"",EOMONTH($D7,J$10))),"") | ... Z15: =IFERROR(IF(EOMONTH($D7,Z$10)=EOMONTH($E7,0),$E7,IF(EOMONTH($D7,Z$10)>EOMONTH($E7,0),"",EOMONTH($D7,Z$10))),"") | AB15: =IF($A7="","",$A7) | AC15: =IF($L$3>=B15,$L$3,B15) | AD15: =IF($L$3>=C15,$L$3,C15) | AE15: =IF($L$3>=D15,$L$3,D15) | AF15: =IF($L$3>=E15,$L$3,E15) | AG15: =IF($L$3>=F15,$L$3,F15) | AH15: =IF($L$3>=G15,$L$3,G15) | AI15: =IF($L$3>=H15,$L$3,H15) | AJ15: =IF($L$3>=I15,$L$3,I15) | ... BA15: =IF($L$3>=Z15,$L$3,Z15) | BC15: =IF($A7="","",$A7) | BD15: =IFERROR(ROUND(IF(BD$10=0,B15-$D7,IF(AC15=$E7,(B15-A15),B15-A15)),0),"") | BE15: =IFERROR(ROUND(IF(BE$10=0,C15-$D7,IF(AD15=$E7,(C15-B15),C15-B15)),0),"") | BF15: =IFERROR(ROUND(IF(BF$10=0,D15-$D7,IF(AE15=$E7,(D15-C15),D15-C15)),0),"") | BG15: =IFERROR(ROUND(IF(BG$10=0,E15-$D7,IF(AF15=$E7,(E15-D15),E15-D15)),0),"") | BH15: =IFERROR(ROUND(IF(BH$10=0,F15-$D7,IF(AG15=$E7,(F15-E15),F15-E15)),0),"") | BI15: =IFERROR(ROUND(IF(BI$10=0,G15-$D7,IF(AH15=$E7,(G15-F15),G15-F15)),0),"") | BJ15: =IFERROR(ROUND(IF(BJ$10=0,H15-$D7,IF(AI15=$E7,(H15-G15),H15-G15)),0),"") | BK15: =IFERROR(ROUND(IF(BK$10=0,I15-$D7,IF(AJ15=$E7,(I15-H15),I15-H15)),0),"") | ... CB15: =IFERROR(ROUND(IF(CB$10=0,Z15-$D7,IF(BA15=$E7,(Z15-Y15),Z15-Y15)),0),"") | CD15: =IF($A7="","",$A7) | CE15: =IFERROR(IF(B15="","",$G7*BD15),"") | CF15: =IFERROR(IF(C15="","",$G7*BE15),"") | CG15: =IFERROR(IF(D15="","",$G7*BF15),"") | CH15: =IFERROR(IF(E15="","",$G7*BG15),"") | CI15: =IFERROR(IF(F15="","",$G7*BH15),"") | CJ15: =IFERROR(IF(G15="","",$G7*BI15),"") | CK15: =IFERROR(IF(H15="","",$G7*BJ15),"") | CL15: =IFERROR(IF(I15="","",$G7*BK15),"") | ... DC15: =IFERROR(IF(Z15="","",$G7*CB15),"")
A17: BALANCES
A18: AttributeID | B18: Date | C18: Billing | D18: Revenue | E18: Unbilled | F18: Deferred Revenue
A19: 0 | B19: =IF(A19="","",$L$3) -> 44620.229 | C19: {=VLOOKUP(A19,VALUE(EOD!$D$2:$H$6),2,FALSE)-(INV!E2+INV!F2)} -> 0 | D19: 0 | E19: {=VLOOKUP(A19,VALUE(EOD!$D$2:$H$6),3,FALSE)} -> 342.818 | F19: =IF(A19="","",SUM(EOD!H2:H7)) -> 1899.9999
A20: =IF($B3="","",$B3) -> 1 | B20: =IF(A20="","",$L$3) -> 44620.229 | C20: =IF(A20="","",0) -> 0 | D20: =IF(A20="","",EOD!G3) -> 0 | E20: =IF(A20="","",0) -> 0 | F20: =IF(A20="","",0) -> 0
A21: =IF($B4="","",$B4) -> 2 | B21: =IF(A21="","",$L$3) -> 44620.229 | C21: =IF(A21="","",0) -> 0 | D21: =IF(A21="","",EOD!G4) -> -47.593 | E21: =IF(A21="","",0) -> 0 | F21: =IF(A21="","",0) -> 0
A22: =IF($B5="","",$B5) -> 3 | B22: =IF(A22="","",$L$3) -> 44620.229 | C22: =IF(A22="","",0) -> 0 | D22: =IF(A22="","",EOD!G5) -> -271.4286 | E22: =IF(A22="","",0) -> 0 | F22: =IF(A22="","",0) -> 0
A23: =IF($B6="","",$B6) -> 4 | B23: =IF(A23="","",$L$3) -> 44620.229 | C23: =IF(A23="","",0) -> 0 | D23: =IF(A23="","",EOD!G6) -> -23.7965 | E23: =IF(A23="","",0) -> 0 | F23: =IF(A23="","",0) -> 0
A24: =IF($B7="","",$B7) | B24: =IF(A24="","",$L$3) | C24: =IF(A24="","",0) | D24: =IF(A24="","",EOD!G7) | E24: =IF(A24="","",0) | F24: =IF(A24="","",0)
A25: Total | C25: =SUM(C19:C24) -> 0 | D25: =SUM(D19:D24) -> -342.8181 | E25: =SUM(E19:E24) -> 342.818 | F25: =SUM(F19:F24) -> 1899.9999
A27: NEW ACTIVITY + BALANCE
A28: AttributeID | B28: Date | C28: Billing | D28: Revenue | E28: Unbilled | F28: Deferred Revenue
A29: 0 | B29: =IF(A29="","",$L$3) -> 44620.229 | C29: =IF(B29="","",C25+C37) -> 1900 | D29: =IF(B29="","",0) -> 0 | E29: =IF(B29="","",IF(SUM(C29:D34)>0,0,-SUM(C29:D34))) -> 0 | F29: =IF(B29="","",SUM(C29:E34)) -> 1432.2505
A30: =IF($B3="","",$B3) -> 1 | B30: =IF(A30="","",$L$3) -> 44620.229 | C30: =IF(A30="","",0) -> 0 | D30: =IF(B30="","",-SUMIF($AC11:$BA11,$L$3,$CE11:$DC11)) -> 0 | E30: =IF(A30="","",0) -> 0 | F30: =IF(A30="","",0) -> 0
A31: =IF($B4="","",$B4) -> 2 | B31: =IF(A31="","",$L$3) -> 44620.229 | C31: =IF(A31="","",0) -> 0 | D31: =IF(B31="","",-SUMIF($AC12:$BA12,$L$3,$CE12:$DC12)) -> -130.88063 | E31: =IF(A31="","",0) -> 0 | F31: =IF(A31="","",0) -> 0
A32: =IF($B5="","",$B5) -> 3 | B32: =IF(A32="","",$L$3) -> 44620.229 | C32: =IF(A32="","",0) -> 0 | D32: =IF(B32="","",-SUMIF($AC13:$BA13,$L$3,$CE13:$DC13)) -> -271.42857 | E32: =IF(A32="","",0) -> 0 | F32: =IF(A32="","",0) -> 0
A33: =IF($B6="","",$B6) -> 4 | B33: =IF(A33="","",$L$3) -> 44620.229 | C33: =IF(A33="","",0) -> 0 | D33: =IF(B33="","",-SUMIF($AC14:$BA14,$L$3,$CE14:$DC14)) -> -65.440313 | E33: =IF(A33="","",0) -> 0 | F33: =IF(A33="","",0) -> 0
A34: =IF($B7="","",$B7) | B34: =IF(A34="","",$L$3) | C34: =IF(A34="","",0) | D34: =IF(B34="","",-SUMIF($AC15:$BA15,$L$3,$CE15:$DC15)) | E34: =IF(A34="","",0) | F34: =IF(A34="","",0)
A35: NEW ACTIVITY
A37: 0 | B37: =IF(A37="","",$L$3) -> 44620.229 | C37: =INV!E2+INV!F2 -> 1900 | D37: =IF(B37="","",0) -> 0 | E37: =IF(B37="","",IF(SUM(C37:D42)>0,0,-SUM(C37:D42))) -> 0 | F37: =IF(B37="","",SUM(C37:E42)) -> 1775.0686
A38: =IF($B3="","",$B3) -> 1 | B38: =IF(A38="","",$L$3) -> 44620.229 | C38: =IF(A38="","",0) -> 0 | D38: =IF(B38="","",D30-D20) -> 0 | E38: =IF(A38="","",0) -> 0 | F38: =IF(A38="","",0) -> 0
A39: =IF($B4="","",$B4) -> 2 | B39: =IF(A39="","",$L$3) -> 44620.229 | C39: =IF(A39="","",0) -> 0 | D39: =IF(B39="","",D31-D21) -> -83.287626 | E39: =IF(A39="","",0) -> 0 | F39: =IF(A39="","",0) -> 0
A40: =IF($B5="","",$B5) -> 3 | B40: =IF(A40="","",$L$3) -> 44620.229 | C40: =IF(A40="","",0) -> 0 | D40: =IF(B40="","",D32-D22) -> 2.8571428e-05 | E40: =IF(A40="","",0) -> 0 | F40: =IF(A40="","",0) -> 0
A41: =IF($B6="","",$B6) -> 4 | B41: =IF(A41="","",$L$3) -> 44620.229 | C41: =IF(B41="","",C33+$C$25) -> 0 | D41: =IF(B41="","",D33-D23) -> -41.643813 | E41: =IF(A41="","",0) -> 0 | F41: =IF(A41="","",0) -> 0
A42: =IF($B7="","",$B7) | B42: =IF(A42="","",$L$3) | C42: =IF(B42="","",C34+$C$25) | D42: =IF(B42="","",D34-D24) | E42: =IF(A42="","",0) | F42: =IF(A42="","",0)
A44: TRANSACTIONS
A45: PostingDate | B45: TransactionDate | C45: InstrumentId | D45: Transactiontype | E45: Amount | F45: AttributeId | G45: Group
...

Sheet Events
A1: Table | B1: Field | C1: Event | E1: Trigger
A2: Attribute | B2: Productdid | C2: REV | E2: Model Execution
A3: Attribute | B3: AttributeID | C3: REV
A4: Attribute | B4: StartDate | C4: REV
A5: Attribute | B5: Enddate | C5: REV
A6: Attribute | B6: Instrumentid | C6: REV
A7: Attribute | B7: SalePrice | C7: REV
A8: Attribute | B8: Quantity | C8: REV
A9: Balances | B9: Beg.Billing | C9: EOD | E9: Model Execution
A10: Balances | B10: Beg.DeferredRev | C10: EOD
A11: Balances | B11: Beg.unbilled | C11: EOD
A12: Balances | B12: Beg.Revenue | C12: EOD
A13: Transactions | B13: Amount.Billing | C13: INV | E13: TransactionPost | G13: Billing,Credit_Note
A14: Transactions | B14: Amount.CreditNote | C14: INV

Sheet o_Transaction
A1: PostingDate | B1: TransactionDate | C1: InstrumentId | D1: TransactionName | E1: Amount | F1: AttributeId
A2: =IF(RevRec_Calc!A46="","",RevRec_Calc!A46) | B2: =IF(A2="","",RevRec_Calc!B46) | C2: =IF(A2="","",RevRec_Calc!C46) | D2: =IF(A2="","",RevRec_Calc!D46) | E2: =IF(A2="","",RevRec_Calc!E46) | F2: =IF(A2="","",RevRec_Calc!F46)
A3: =IF(RevRec_Calc!A47="","",RevRec_Calc!A47) -> 44620.229 | B3: =IF(A3="","",RevRec_Calc!B47) -> 44620.229 | C3: =IF(A3="","",RevRec_Calc!C47) -> SO1 | D3: =IF(A3="","",RevRec_Calc!D47) -> Revenue | E3: =IF(A3="","",RevRec_Calc!E47) -> -83.287626 | F3: =IF(A3="","",RevRec_Calc!F47) -> 2
A4: =IF(RevRec_Calc!A48="","",RevRec_Calc!A48) -> 44620.229 | B4: =IF(A4="","",RevRec_Calc!B48) -> 44620.229 | C4: =IF(A4="","",RevRec_Calc!C48) -> SO1 | D4: =IF(A4="","",RevRec_Calc!D48) -> Revenue | E4: =IF(A4="","",RevRec_Calc!E48) -> 2.8571428e-05 | F4: =IF(A4="","",RevRec_Calc!F48) -> 3
A5: =IF(RevRec_Calc!A49="","",RevRec_Calc!A49) -> 44620.229 | B5: =IF(A5="","",RevRec_Calc!B49) -> 44620.229 | C5: =IF(A5="","",RevRec_Calc!C49) -> SO1 | D5: =IF(A5="","",RevRec_Calc!D49) -> Revenue | E5: =IF(A5="","",RevRec_Calc!E49) -> -41.643813 | F5: =IF(A5="","",RevRec_Calc!F49) -> 4
A6: =IF(RevRec_Calc!A50="","",RevRec_Calc!A50) | B6: =IF(A6="","",RevRec_Calc!B50) | C6: =IF(A6="","",RevRec_Calc!C50) | D6: =IF(A6="","",RevRec_Calc!D50) | E6: =IF(A6="","",RevRec_Calc!E50) | F6: =IF(A6="","",RevRec_Calc!F50)
A7: =IF(RevRec_Calc!A51="","",RevRec_Calc!A51) -> 44620.229 | B7: =IF(A7="","",RevRec_Calc!B51) -> 44620.229 | C7: =IF(A7="","",RevRec_Calc!C51) -> SO1 | D7: =IF(A7="","",RevRec_Calc!D51) -> Unbilled_Charge | E7: =IF(A7="","",RevRec_Calc!E51) -> -342.818 | F7: =IF(A7="","",RevRec_Calc!F51) -> 0

Sheet EXPECTED_INP_OUT
A1: 44592 | L1: OUTPUT
A2: REV
A3: PostingDate | B3: EffectiveDate | C3: InstrumentId | D3: AttributeId | E3: ATTRIBUTES.PRODUCTID.CURRENT | F3: ATTRIBUTES.STARTDATE.CURRENT | G3: ATTRIBUTES.ENDDATE.CURRENT | H3: ATTRIBUTES.SALEPRICE.CURRENT | I3: ATTRIBUTES.QUANTITY.CURRENT | L3: PostingDate | M3: TransactionDate | N3: InstrumentId | O3: TransactionName | P3: Amount | Q3: AttributeId
A4: 44592 | B4: 44592 | C4: SO1 | D4: 0 | E4: 0 | L4: 44592 | M4: 44592 | N4: SO1 | O4: Revenue | P4: -47.592955 | Q4: 2
A5: 44592 | B5: 44592 | C5: SO1 | D5: 1 | E5: 1 | F5: 44576 | G5: 44576 | H5: -200 | I5: 1 | L5: 44592 | M5: 44592 | N5: SO1 | O5: Revenue | P5: -271.42857 | Q5: 3
A6: 44592 | B6: 44592 | C6: SO1 | D6: 2 | E6: 2 | F6: 44576 | G6: 44941 | H6: 100 | I6: 12 | L6: 44592 | M6: 44592 | N6: SO1 | O6: Revenue | P6: -23.796477 | Q6: 4
A7: 44592 | B7: 44592 | C7: SO1 | D7: 3 | E7: 3 | F7: 44576 | G7: 44576 | H7: 300 | I7: 1 | L7: 44592 | M7: 44592 | N7: SO1 | O7: Unbilled Charge | P7: 342.818 | Q7: 0
A8: 44592 | B8: 44592 | C8: SO1 | D8: 4 | E8: 5 | F8: 44576 | G8: 44941 | H8: 50 | I8: 12
A10: INV
A11: PostingDate | B11: EffectiveDate | C11: InstrumentId | D11: AttributeId | E11: TRANSACTIONS.AMOUNT.NEW_BILLING | F11: TRANSACTIONS.AMOUNT.CREDIT_NOTE
A13: EOD
A14: PostingDate | B14: EffectiveDate | C14: InstrumentId | D14: AttributeId | E14: BALANCES.BEGINNINGBALANCE.BILLING | F14: BALANCES.BEGINNINGBALANCE.UNBILLED | G14: BALANCES.BEGINNINGBALANCE.REVENUE | H14: BALANCES.BEGINNINGBALANCE.DEFERRED_REVENUE
A19: 44620 | L19: OUTPUT
A20: REV
A21: PostingDate | B21: EffectiveDate | C21: InstrumentId | D21: AttributeId | E21: ATTRIBUTES.PRODUCTID.CURRENT | F21: ATTRIBUTES.STARTDATE.CURRENT | G21: ATTRIBUTES.ENDDATE.CURRENT | H21: ATTRIBUTES.SALEPRICE.CURRENT | I21: ATTRIBUTES.QUANTITY.CURRENT | L21: PostingDate | M21: TransactionDate | N21: InstrumentId | O21: TransactionName | P21: Amount | Q21: AttributeId
A22: 44592 | B22: 44592 | C22: SO1 | D22: 0 | E22: 0 | L22: 44620 | M22: 44620 | N22: SO1 | O22: Revenue | P22: -83.287671 | Q22: 2
A23: 44592 | B23: 44592 | C23: SO1 | D23: 1 | E23: 1 | F23: 44576 | G23: 44576 | H23: -200 | I23: 1 | L23: 44620 | M23: 44620 | N23: SO1 | O23: Revenue | P23: -3.9790393e-13 | Q23: 3
A24: 44592 | B24: 44592 | C24: SO1 | D24: 2 | E24: 2 | F24: 44576 | G24: 44941 | H24: 100 | I24: 12 | L24: 44620 | M24: 44620 | N24: SO1 | O24: Revenue | P24: -41.643836 | Q24: 4
A25: 44592 | B25: 44592 | C25: SO1 | D25: 3 | E25: 3 | F25: 44576 | G25: 44576 | H25: 300 | I25: 1 | L25: 44620 | M25: 44620 | N25: SO1 | O25: Unbilled Charge | P25: -342.818 | Q25: 0
A26: 44592 | B26: 44592 | C26: SO1 | D26: 4 | E26: 5 | F26: 44576 | G26: 44941 | H26: 50 | I26: 12
A28: INV
A29: PostingDate | B29: EffectiveDate | C29: InstrumentId | D29: AttributeId | E29: TRANSACTIONS.AMOUNT.NEW_BILLING | F29: TRANSACTIONS.AMOUNT.CREDIT_NOTE
A30: 44620 | B30: 44620 | C30: SO1 | D30: 0 | E30: 1900 | F30: 0
A32: EOD
A33: PostingDate | B33: EffectiveDate | C33: InstrumentId | D33: AttributeId | E33: BALANCES.BEGINNINGBALANCE.BILLING | F33: BALANCES.BEGINNINGBALANCE.UNBILLED | G33: BALANCES.BEGINNINGBALANCE.REVENUE | H33: BALANCES.BEGINNINGBALANCE.DEFERRED_REVENUE
A34: 44620 | B34: 44620 | C34: SO1 | D34: 0 | E34: 1900 | F34: 342.818 | G34: 0 | H34: 342.818
A35: 44620 | B35: 44620 | C35: SO1 | D35: 1 | E35: 0 | F35: 0 | G35: 0 | H35: 0
A36: 44620 | B36: 44620 | C36: SO1 | D36: 2 | E36: 0 | F36: 0 | G36: -47.592955 | H36: -47.593
A37: 44620 | B37: 44620 | C37: SO1 | D37: 3 | E37: 0 | F37: 0 | G37: -271.42857 | H37: -271.4286
A38: 44620 | B38: 44620 | C38: SO1 | D38: 4 | E38: 0 | F38: 0 | G38: -23.796477 | H38: -23.7965
A41: 44651 | L41: OUTPUT
A43: PostingDate | B43: EffectiveDate | C43: InstrumentId | D43: AttributeId | E43: ATTRIBUTES.PRODUCTID.CURRENT | F43: ATTRIBUTES.STARTDATE.CURRENT | G43: ATTRIBUTES.ENDDATE.CURRENT | H43: ATTRIBUTES.SALEPRICE.CURRENT | I43: ATTRIBUTES.QUANTITY.CURRENT | L43: PostingDate | M43: TransactionDate | N43: InstrumentId | O43: TransactionName | P43: Amount | Q43: AttributeId
A44: 44592 | B44: 44592 | C44: SO1 | D44: 0 | E44: 0 | L44: 44651 | M44: 44651 | N44: SO1 | O44: Revenue | P44: -92.211377 | Q44: 2
A45: 44592 | B45: 44592 | C45: SO1 | D45: 1 | E45: 1 | F45: 44576 | G45: 44576 | H45: -200 | I45: 1 | L45: 44651 | M45: 44651 | N45: SO1 | O45: Revenue | P45: 2.8571429e-05 | Q45: 3
A46: 44592 | B46: 44592 | C46: SO1 | D46: 2 | E46: 2 | F46: 44576 | G46: 44941 | H46: 100 | I46: 12 | L46: 44651 | M46: 44651 | N46: SO1 | O46: Revenue | P46: -46.105688 | Q46: 4
A47: 44592 | B47: 44592 | C47: SO1 | D47: 3 | E47: 3 | F47: 44576 | G47: 44576 | H47: 300 | I47: 1
A48: 44592 | B48: 44592 | C48: SO1 | D48: 4 | E48: 5 | F48: 44576 | G48: 44941 | H48: 50 | I48: 12
A50: INV
A51: PostingDate | B51: EffectiveDate | C51: InstrumentId | D51: AttributeId | E51: TRANSACTIONS.AMOUNT.NEW_BILLING | F51: TRANSACTIONS.AMOUNT.CREDIT_NOTE
A53: EOD
...

Sheet Scenario
A2: Transactions | H2: Ending Balance | M2: General Ledger
A3: PD | B3: ED | C3: Transaction | D3: Amount | E3: EntryType | F3: AttributeID | H3: Billing | I3: Revenue | J3: Unbilled | K3: Deferred Revenue | M3: Month | N3: Account | O3: DR | P3: CR
A4: 44592 | B4: =A4 -> 44592 | C4: Revenue | D4: -47.592955 | E4: Model | F4: 2 | M4: Jan | N4: Deferred Revenue | O4: =-I7 -> 342.818
A5: 44592 | B5: =A5 -> 44592 | C5: Revenue | D5: -271.42857 | E5: Model | F5: 3 | N5: Revenue | P5: =I7 -> -342.818 | AE5: Balance | AF5: Balance | AG5: Activity | AH5: Activity | AI5: Balance | AJ5: Balance
A6: 44592 | B6: 44592 | C6: Revenue | D6: -23.796477 | E6: Model | F6: 4 | N6: Unbilled Charge | O6: =J7 -> 342.818
A7: 44592 | B7: 44592 | C7: Unbilled Charge | D7: 342.818 | E7: Model | F7: 0 | H7: 0 | I7: =SUM(D4:D6) -> -342.818 | J7: =D7 -> 342.818 | K7: =SUM(H7:J7) -> 1.7053026e-13 | N7: Deferred Revenue | P7: =-O6 -> -342.818
A8: 44620 | B8: 44620 | C8: Revenue | D8: -83.287671 | E8: Model | F8: 2
A9: 44620 | B9: 44620 | C9: Revenue | D9: -41.643836 | E9: Model | F9: 4 | M9: Feb | N9: Deferred Revenue | O9: =-(D8+D9) -> 124.93151
A10: 44620 | B10: 44620 | C10: Unbilled Charge | D10: -342.818 | E10: Model | F10: 0 | N10: Revenue | P10: =-O9 -> -124.93151
A11: 44620 | B11: 44620 | C11: New Billing | D11: 1900 | E11: ETL | F11: 0 | H11: =D11 -> 1900 | I11: =D8+D9+I7 -> -467.74951 | J11: =J7+D10 -> 0 | K11: =SUM(H11:J11) -> 1432.2505 | N11: Deferred Revenue | O11: =-D10 -> 342.818
A12: 44651 | B12: 44651 | C12: Revenue | D12: -92.21135 | E12: Model | F12: 2 | N12: Unbilled Charge | P12: =D10 -> -342.818
A13: 44651 | B13: 44651 | C13: Revenue | D13: -46.105675 | E13: Model | F13: 4 | H13: =H11 -> 1900 | I13: =I11+D12+D13 -> -606.06654 | J13: =J11 -> 0 | K13: =K11+D12+D13 -> 1293.9335 | N13: Contra Revenue | O13: =H11 -> 1900
A14: 44681 | B14: =B4 -> 44592 | C14: =C4 -> Revenue | D14: =-D4 -> 47.592955 | E14: Reversal | F14: =F4 -> 2 | N14: Deferred Revenue | P14: =-O13 -> -1900
A15: 44681 | B15: =B5 -> 44592 | C15: =C5 -> Revenue | D15: =-D5 -> 271.42857 | E15: Reversal | F15: =F5 -> 3
A16: 44681 | B16: =B6 -> 44592 | C16: =C6 -> Revenue | D16: =-D6 -> 23.796477 | E16: Reversal | F16: =F6 -> 4 | M16: Mar | N16: Deferred Revenue | O16: =-(D12+D13) -> 138.31703
A17: 44681 | B17: =B7 -> 44592 | C17: =C7 -> Unbilled Charge | D17: =-D7 -> -342.818 | E17: Reversal | F17: =F7 -> 0 | N17: Revenue | P17: =-O16 -> -138.31703
A18: 44681 | B18: =B8 -> 44620 | C18: =C8 -> Revenue | D18: =-D8 -> 83.287671 | E18: Reversal | F18: =F8 -> 2
A19: 44681 | B19: =B9 -> 44620 | C19: =C9 -> Revenue | D19: =-D9 -> 41.643836 | E19: Reversal | F19: =F9 -> 4 | M19: Apr | N19: Deferred Revenue | O19: =-P20 -> 310.98065
A20: 44681 | B20: =B10 -> 44620 | C20: =C10 -> Unbilled Charge | D20: =-D10 -> 342.818 | E20: Reversal | F20: =F10 -> 0 | N20: Revenue | P20: =I25-I13 -> -310.98065
A21: 44681 | B21: =B13 -> 44651 | C21: =C12 -> Revenue | D21: =-D12 -> 92.21135 | E21: Reversal | F21: =F12 -> 2
A22: 44681 | B22: =B21 -> 44651 | C22: =C13 -> Revenue | D22: =-D13 -> 46.105675 | E22: Reversal | F22: =F13 -> 4 | H22: =H13 -> 1900 | I22: =I13+D14+D15+D16+D18+D19+D21+D22 -> 4.9737992e-14 | J22: =D17+D20 -> 0 | K22: =H22 -> 1900 | M22: May | N22: Contra Revenue | O22: =D26 -> 600
A23: 44681 | B23: 44681 | C23: Revenue | D23: -319.6347 | E23: Model | F23: 2 | N23: Deferred Revenue | P23: =-O22 -> -600
A24: 44681 | B24: 44681 | C24: Revenue | D24: -277.77778 | E24: Model | F24: 3 | N24: Deferred Revenue | O24: =-P25 -> 188.73668
A25: 44681 | B25: 44681 | C25: Revenue | D25: -319.6347 | E25: Model | F25: 4 | H25: =H13 -> 1900 | I25: =D23+D24+D25 -> -917.04718 | J25: =J13 -> 0 | K25: =K22+D23+D24+D25 -> 982.95282 | N25: Revenue | P25: =D27+D28 -> -188.73668
A26: 44712 | B26: 44712 | C26: New Billing | D26: 600 | E26: ETL | F26: 0
A27: 44712 | B27: 44712 | C27: Revenue | D27: -94.368341 | E27: Model | F27: 2
A28: 44712 | B28: 44712 | C28: Revenue | D28: -94.368341 | E28: Model | F28: 4 | H28: =H25+D26 -> 2500 | I28: =I25+D27+D28 -> -1105.7839 | K28: =K25+D26+D27+D28 -> 1394.2161
